2023-04-04 22:09:41,223 - INFO - script started
2023-04-04 22:09:41,223 - INFO - reading defined url
2023-04-04 22:09:41,223 - INFO - GET request
2023-04-04 22:09:41,240 - ERROR - An unexpected error occurred: <urlopen error [Errno -2] Name or service not known>
Traceback (most recent call last):
  File "/usr/lib64/python3.11/urllib/request.py", line 1348, in do_open
    h.request(req.get_method(), req.selector, req.data, headers,
  File "/usr/lib64/python3.11/http/client.py", line 1282, in request
    self._send_request(method, url, body, headers, encode_chunked)
  File "/usr/lib64/python3.11/http/client.py", line 1328, in _send_request
    self.endheaders(body, encode_chunked=encode_chunked)
  File "/usr/lib64/python3.11/http/client.py", line 1277, in endheaders
    self._send_output(message_body, encode_chunked=encode_chunked)
  File "/usr/lib64/python3.11/http/client.py", line 1037, in _send_output
    self.send(msg)
  File "/usr/lib64/python3.11/http/client.py", line 975, in send
    self.connect()
  File "/usr/lib64/python3.11/http/client.py", line 1447, in connect
    super().connect()
  File "/usr/lib64/python3.11/http/client.py", line 941, in connect
    self.sock = self._create_connection(
                ^^^^^^^^^^^^^^^^^^^^^^^^
  File "/usr/lib64/python3.11/socket.py", line 827, in create_connection
    for res in getaddrinfo(host, port, 0, SOCK_STREAM):
               ^^^^^^^^^^^^^^^^^^^^^^^^^^^^^^^^^^^^^^^
  File "/usr/lib64/python3.11/socket.py", line 962, in getaddrinfo
    for res in _socket.getaddrinfo(host, port, family, type, proto, flags):
               ^^^^^^^^^^^^^^^^^^^^^^^^^^^^^^^^^^^^^^^^^^^^^^^^^^^^^^^^^^^
socket.gaierror: [Errno -2] Name or service not known

During handling of the above exception, another exception occurred:

Traceback (most recent call last):
  File "/home/haui/Dokumente/PROGRAMMIEREN/Python/webScraper/webScraper.py", line 26, in <module>
    response = urlopen(url).read()
               ^^^^^^^^^^^^
  File "/usr/lib64/python3.11/urllib/request.py", line 216, in urlopen
    return opener.open(url, data, timeout)
           ^^^^^^^^^^^^^^^^^^^^^^^^^^^^^^^
  File "/usr/lib64/python3.11/urllib/request.py", line 519, in open
    response = self._open(req, data)
               ^^^^^^^^^^^^^^^^^^^^^
  File "/usr/lib64/python3.11/urllib/request.py", line 536, in _open
    result = self._call_chain(self.handle_open, protocol, protocol +
             ^^^^^^^^^^^^^^^^^^^^^^^^^^^^^^^^^^^^^^^^^^^^^^^^^^^^^^^
  File "/usr/lib64/python3.11/urllib/request.py", line 496, in _call_chain
    result = func(*args)
             ^^^^^^^^^^^
  File "/usr/lib64/python3.11/urllib/request.py", line 1391, in https_open
    return self.do_open(http.client.HTTPSConnection, req,
           ^^^^^^^^^^^^^^^^^^^^^^^^^^^^^^^^^^^^^^^^^^^^^^
  File "/usr/lib64/python3.11/urllib/request.py", line 1351, in do_open
    raise URLError(err)
urllib.error.URLError: <urlopen error [Errno -2] Name or service not known>
2023-04-04 22:09:41,241 - ERROR - exiting the script
